Workbook

Sheet FieldBeat-Zendesk
A1: Ticket ID | B1: Asunto | C1: Estado | D1: Prioridad | E1: Tipo | F1: Fecha Creación (ZD) | G1: Fecha Última Actualización (ZD) | H1: Cliente (Nombre) | I1: Técnico (Nombre) | J1: Solicitante ID | K1: Tiene Visita? | L1: FB Task ID | M1: Inicio Trabajo (FB) | N1: Término Trabajo (FB) | O1: Máquina (FB) | P1: Es Inhábil? | Q1: Duración Trabajo (Minutos) | R1: Tags
A2: 9821 | B2: solicitud cambio de thyratron | C2: pending | D2: urgent | E2: incident | F2: 46042.448 | G2: 46042.484 | H2: INRAD | I2: Sin Asignar | J2: 38368479928987 | K2: SI | L2: 3479 | M2: 46042.584 | O2: Linac-201172 | P2: 0 | R2: Origen: Zendesk
A3: 9817 | B3: Solicitud de conexión para el TRM | C3: pending | D3: low | E3: incident | F3: 46041.52 | G3: 46041.522 | H3: Hospital Clinico de Magallanes | I3: Sin Asignar | J3: 26132276827035 | K3: NO | P3: 0 | R3: Origen: Zendesk
A4: 9816 | B4: Falla del tubo de rayos X | C4: new | D4: urgent | E4: incident | F4: 46037.638 | G4: 46037.642 | H4: Instituto Nacional del Cancer | I4: Sin Asignar | J4: 35062929091611 | K4: SI | L4: 3473 | M4: 46041.622 | O4: N/A | P4: 0 | R4: Origen: Zendesk
A5: 9812 | B5: Table long | C5: solved | D5: high | E5: incident | F5: 46036.584 | G5: 46037.668 | H5: Hospital Clinico de Magallanes | I5: Sin Asignar | J5: 26080982926747 | K5: NO | P5: 0 | R5: Origen: Zendesk
A6: 9811 | B6: Se solicita calibración de láseres de sala de equipo Versa | C6: new | D6: high | E6: incident | F6: 46036.544 | G6: 46036.544 | H6: Clinica Alemana | I6: Sin Asignar | J6: 36182421530907 | K6: SI | L6: 3491 | M6: 46048.45 | O6: N/A | P6: 0 | R6: Origen: Zendesk
A7: 9809 | B7: Panel iview | C7: open | D7: normal | E7: incident | F7: 46036.448 | G7: 46037.45 | H7: Hospital Clinico de Magallanes | I7: Sin Asignar | J7: 26080982926747 | K7: NO | P7: 0 | R7: Origen: Zendesk
A8: 9809 | B8: Panel iview | C8: open | D8: normal | E8: incident | F8: 46036.448 | G8: 46042.445 | H8: Hospital Clinico de Magallanes | I8: Sin Asignar | J8: 26080982926747 | K8: NO | P8: 0 | R8: Origen: Zendesk
A9: 9807 | B9: Equipo no logra iniciar | C9: solved | D9: high | E9: incident | F9: 46035.465 | G9: 46037.501 | H9: Clinica Alemana | I9: Sin Asignar | J9: 36182421530907 | K9: NO | P9: 0 | R9: Origen: Zendesk
A10: 9807 | B10: Equipo no logra iniciar | C10: closed | D10: high | E10: incident | F10: 46035.465 | G10: 46040.518 | H10: Clinica Alemana | I10: Sin Asignar | J10: 36182421530907 | K10: NO | P10: 0 | R10: Origen: Zendesk
A11: 9806 | B11: Interlock PRF En Chk | C11: pending | D11: high | E11: incident | F11: 46034.977 | G11: 46037.643 | H11: UC Christus SCA | I11: Sin Asignar | J11: 20254050952987 | K11: SI | L11: 3462 | M11: 46037.449 | O11: Linac-109256 | P11: 0 | R11: Origen: Zendesk
A12: 9805 | B12: System on water temp | C12: solved | D12: high | E12: incident | F12: 46034.468 | G12: 46036.751 | H12: Hospital Clinico de Magallanes | I12: Sin Asignar | J12: 26080982926747 | K12: NO | P12: 0 | R12: Origen: Zendesk
A13: 9804 | B13: Calibración hexapod | C13: solved | D13: high | E13: incident | F13: 46031.721 | G13: 46037.629 | H13: UC Christus SCA | I13: Sin Asignar | J13: 20254050952987 | K13: NO | P13: 0 | R13: Origen: Zendesk
A14: 9804 | B14: Calibración hexapod | C14: solved | D14: high | E14: incident | F14: 46031.721 | G14: 46039.656 | H14: UC Christus SCA | I14: Sin Asignar | J14: 20254050952987 | K14: NO | P14: 0 | R14: Origen: Zendesk
A15: 9801 | B15: Gantry Stop-Infinity detenido - se requiere atencion en terreno lo antes posible | C15: closed | D15: urgent | E15: incident | F15: 46030.804 | G15: 46035.561 | H15: Instituto Nacional del Cancer | I15: Sin Asignar | J15: 20254050947483 | K15: SI | L15: 3459 | M15: 46030.823 | O15: N/A | P15: 1 | R15: Origen: Zendesk
A16: 9800 | B16: Solicitud de actualizacion de licencias productos Sunnuclear | C16: new | D16: urgent | E16: incident | F16: 46030.601 | G16: 46030.601 | H16: Instituto Nacional del Cancer | I16: Sin Asignar | J16: 20254050948123 | K16: NO | P16: 0 | R16: Origen: Zendesk
A17: 9799 | B17: Interlocks MLC VERSA 1 | C17: solved | D17: high | E17: incident | F17: 46029.469 | G17: 46037.501 | H17: Clinica las Condes | I17: Sin Asignar | J17: 20254020292379 | K17: NO | P17: 0 | R17: Origen: Zendesk
A18: 9799 | B18: Interlocks MLC VERSA 1 | C18: closed | D18: high | E18: incident | F18: 46029.469 | G18: 46040.518 | H18: Clinica las Condes | I18: Sin Asignar | J18: 20254020292379 | K18: NO | P18: 0 | R18: Origen: Zendesk
A19: 9796 | B19: Gantry Stop aleatorio en CL2 Infinity | C19: closed | D19: urgent | E19: incident | F19: 46028.564 | G19: 46035.561 | H19: Instituto Nacional del Cancer | I19: Sin Asignar | J19: 20254050947483 | K19: NO | P19: 0 | R19: Origen: Zendesk
A20: 9795 | B20: Infinity se apaga solo | C20: new | D20: urgent | E20: incident | F20: 46028.478 | G20: 46028.478 | H20: Instituto Nacional del Cancer | I20: Sin Asignar | J20: 20254050947483 | K20: NO | P20: 0 | R20: Origen: Zendesk
A21: 9792 | B21: Perdida conexión Axesse | C21: new | D21: normal | E21: incident | F21: 46027.589 | G21: 46027.589 | H21: UC Christus CECA | I21: Sin Asignar | J21: 23562920769947 | K21: NO | P21: 0 | R21: Origen: Zendesk
A22: 9785 | B22: Maquina se reinicia sola | C22: closed | D22: normal | E22: incident | F22: 46021.599 | G22: 46032.691 | H22: Hospital Clinico de Magallanes | I22: Sin Asignar | J22: 26080982926747 | K22: NO | P22: 0 | R22: Origen: Zendesk
A23: 9783 | B23: advertencia Replace Filter - SunSCAN | C23: pending | D23: high | E23: incident | F23: 46021.533 | G23: 46029.793 | H23: Instituto Nacional del Cancer | I23: Sin Asignar | J23: 20254050947483 | K23: NO | P23: 0 | R23: Origen: Zendesk
A24: 9782 | B24: falla humidificador y AACC del bunker del Infinity | C24: closed | D24: low | E24: incident | F24: 46021.512 | G24: 46028.724 | H24: Instituto Nacional del Cancer | I24: Sin Asignar | J24: 20254050947483 | K24: NO | P24: 0 | R24: Origen: Zendesk
A25: 9781 | B25: Equipo detenido por Problema con "Tasa de dosis baja Canal A" y B | C25: solved | D25: urgent | E25: incident | F25: 46020.746 | G25: 46037.633 | H25: INRAD | I25: Sin Asignar | J25: 38368479928987 | K25: SI | L25: 3447 | M25: 46020.918 | O25: N/A | P25: 1 | R25: Origen: Zendesk
A26: 9778 | B26: Reaparición falla “Gantry Stop” – CL02 Infinity / Ticket 9774 | C26: closed | D26: urgent | E26: incident | F26: 46020.709 | G26: 46032.607 | H26: Instituto Nacional del Cancer | I26: Sin Asignar | J26: 20254050947483 | K26: SI | L26: 3449 | M26: 46024.434 | O26: INC-156473 | P26: 0 | R26: Origen: Zendesk
A27: 9775 | B27: DOSE RATE MON 6MeV INFINITY | C27: closed | D27: normal | E27: incident | F27: 46015.737 | G27: 46024.614 | H27: UC Christus CECA | I27: Sin Asignar | J27: 20254050952347 | K27: SI | L27: 3442 | M27: 46017.513 | O27: Linac-109374 | P27: 0 | R27: Origen: Zendesk
A28: 9774 | B28: falla Gantry Stop - no puedo hacer QA de paciente - Equipo detenido | C28: closed | D28: urgent | E28: incident | F28: 46015.736 | G28: 46019.908 | H28: Instituto Nacional del Cancer | I28: Sin Asignar | J28: 20254050947483 | K28: SI | L28: 3441 | M28: 46020.367 | O28: INC-156473 | P28: 0 | R28: Origen: Zendesk
A29: 9770 | B29: Water Temp | C29: closed | D29: urgent | E29: incident | F29: 46013.655 | G29: 46033.618 | H29: UC Christus SCA | I29: Sin Asignar | J29: 20254050953243 | K29: NO | P29: 0 | R29: Origen: Zendesk
A30: 9764 | B30: Multiples interlocks mas charco de agua en sala de maquinas de origen desconocido | C30: closed | D30: urgent | E30: incident | F30: 46010.494 | G30: 46017.642 | H30: Clinica las Condes | I30: Sin Asignar | J30: 20254020292379 | K30: SI | L30: 3438 | M30: 46010.641 | O30: CLC-1 | P30: 0 | R30: Origen: Zendesk
A31: 9762 | B31: Solicitud de MP Flexitro | C31: new | D31: normal | E31: incident | F31: 46009.542 | G31: 46036.634 | H31: UC Christus CECA | I31: Sin Asignar | J31: 20254050952347 | K31: NO | P31: 0 | R31: Origen: Zendesk
A32: 9751 | B32: Table long | C32: closed | E32: incident | F32: 46006.519 | G32: 46006.86 | H32: Hospital Clinico de Magallanes | I32: Sin Asignar | J32: 26080982926747 | K32: NO | P32: 0 | R32: Origen: Zendesk
A33: 9749 | B33: Dose rate mon | C33: closed | D33: urgent | E33: incident | F33: 46003.519 | G33: 46011.676 | H33: Hospital Carlos Van Buren | I33: Sin Asignar | J33: 20254020299291 | K33: SI | L33: 3431 | M33: 46003.575 | O33: N/A | P33: 0 | R33: Origen: Zendesk
A34: 9748 | B34: Importación plan respalado | C34: closed | D34: low | E34: incident | F34: 46003.493 | G34: 46017.514 | H34: Hospital Clinico de Magallanes | I34: Sin Asignar | J34: 40109334283675 | K34: NO | P34: 0 | R34: Origen: Zendesk
H35: Desconocido | I35: Sin Asignar | K35: NO | P35: 0 | R35: Origen: Zendesk
A36: 9746 | B36: Panel de control lateral de camilla está suelto | C36: closed | D36: normal | E36: incident | F36: 46002.736 | G36: 46007.663 | H36: Hospital Clinico de Magallanes | I36: Sin Asignar | J36: 26080969273499 | K36: SI | L36: 3428 | M36: 46003.65 | O36: Linac-109452 | P36: 0 | R36: Origen: Zendesk
A37: 9745 | B37: Interlock Table Long | C37: closed | D37: normal | E37: incident | F37: 46002.626 | G37: 46032.691 | H37: Hospital Clinico de Magallanes | I37: Sin Asignar | J37: 26080969273499 | K37: NO | P37: 0 | R37: Origen: Zendesk
A38: 9743 | B38: Switches sin luz | C38: closed | D38: low | E38: incident | F38: 46002.542 | G38: 46017.514 | H38: Hospital Clinico de Magallanes | I38: Sin Asignar | J38: 26080982926747 | K38: NO | P38: 0 | R38: Origen: Zendesk
A39: 9742 | B39: Conebeam presenta artefacto | C39: closed | D39: high | E39: incident | F39: 46001.851 | G39: 46012.742 | H39: Clinica Alemana | I39: Sin Asignar | J39: 36182421530907 | K39: NO | P39: 0 | R39: Origen: Zendesk
A40: 9740 | B40: verificacion configuracion del Baseline del test de Hancock MLC Suncheck del Infinity | C40: open | D40: urgent | E40: incident | F40: 46001.651 | G40: 46028.664 | H40: Instituto Nacional del Cancer | I40: Sin Asignar | J40: 20254050947483 | K40: NO | P40: 0 | R40: Origen: Zendesk
...

Sheet Reporte_Tickets_Detallado
A1: Timestamp | B1: Id FB | C1: Id Ticket | D1: Status | E1: Cliente | F1: Maquina | G1: Descripcion | H1: MailLink
A2: 46049.888 | B2: 3498 | C2: 9841 | D2: FINISHED | E2: UC CHRISTUS - SCA | F2: Linac-109256 | G2: Se efectua optimizacion de energias 10mv y 10FFF en donde se mantuvo en espera de chequeo dosimetrico por parte de Fisico Medico | H2: https://mail.google.com/mail?extsrc=sync&client=docs&plid=ACUX6DPlGjlflgzT6j_wvNolFqfhh2Wr2yDb0LM
A3: 46049.768 | B3: 3496 | C3: 9867 | D3: FINISHED | E3: UC CHRISTUS - CECA | F3: Linac-109374 | G3: Se efectuo optimizacion de energía de 6MV vía remota con resultados conforme. | H3: https://mail.google.com/mail?extsrc=sync&client=docs&plid=ACUX6DP5bxtS8PPAcUm57-Ldgkhdza2HbJN3S68
A4: 46049.806 | B4: 3495 | C4: 9833 | D4: FINISHED | E4: RADIO ONCOLOGÍA DEL SUR | F4: Linac-156187 | G4: Se reemplaza tarjeta PCB reguladora de Voltaje. Telémetro no funciona con el voltaje nominal de operación (11 vac). Se procede a bajar voltaje de alimentación a 6 vac, logrando una activación aleatoria. | H4: https://mail.google.com/mail?extsrc=sync&client=docs&plid=ACUX6DNNnNaepmv_UQMrG9h9TdAd-CfC4wh_lQc
A5: 46049.748 | B5: 3493 | C5: Tarea Sin Ticket | D5: FINISHED | E5: CLÍNICA LAS CONDES | F5: N/A | G5: prueba | H5: https://mail.google.com/mail?extsrc=sync&client=docs&plid=ACUX6DP954RE8YWKsXedwQLtzQZQhmALy-8_xfc
A6: 46049.899 | B6: 3492 | C6: 9784 | D6: FINISHED | E6: CLINICA ALEMANA DE SANTIAGO | F6: Linac-152171 | G6: se realiza instalacion de vm intellimax en nss del suragility, adicionalmente se revisa backup de integrity verificando que los backup se estan almacenando correctamente en el sequencer | H6: https://mail.google.com/mail?extsrc=sync&client=docs&plid=ACUX6DPK1xW-mmd02VCwrjQKdl-EfplAkfp3zdI
A7: 46048.45 | B7: 3491 | C7: 9811 | D7: FINISHED | E7: CLINICA ALEMANA DE SANTIAGO | F7: N/A | G7: se asiste al inicio del linac, el suragility sin problemas durante la partida y los controles de fisica medica dieron positivamente, el fisico medico me indica que no se esta realizando el back up del equipo de manera automatica, le comente que lo conversare con el grupo de TI de eyg para buscar solucion, en el versa norte se esta presentando un desalineamiento de los laser con respecto a frame de la hexapod lo cual se realizara su respectiva correccion. | H7: https://mail.google.com/mail?extsrc=sync&client=docs&plid=ACUX6DPnoEirxcbN7hu2jbXqiJLa-ExNps6bpoM
A8: 46048.382 | B8: 3490 | C8: Tarea Sin Ticket | D8: FINISHED | E8: HOSPITAL CARLOS VAN BUREN (SSVSA) | F8: Linac-154325 | G8: Se efectua chequeo de equipo posterior a mantenimiento Preventivo de Chiller y Convertidor, AA de sala de equipos conforme | H8: https://mail.google.com/mail?extsrc=sync&client=docs&plid=ACUX6DMoHLiST6pFDdSqE8NIaGisqZA8hSixp8c
A9: 46048.357 | B9: 3488 | C9: Tarea Sin Ticket | D9: FINISHED | E9: HOSPITAL CARLOS VAN BUREN (SSVSA) | F9: Linac-154325 | G9: Se efectuo mantenimiento Preventivo a Chiller , Convertidor y Aire Acondicionado. | H9: https://mail.google.com/mail?extsrc=sync&client=docs&plid=ACUX6DN8VSAmKM3_x_AQLv2_6YQLokoWPUYj1uI
A10: 46046.606 | B10: 3487 | C10: Tarea Sin Ticket | D10: FINISHED | E10: UC CHRISTUS - CECA | F10: N/A | G10: Mantenimiento preventivo Flexitron UC | H10: https://mail.google.com/mail?extsrc=sync&client=docs&plid=ACUX6DMwyYt83kTv7Z4KvO9QCwLCmCWv56DU31Q
A11: 46046.559 | B11: 3486 | C11: 9819 | D11: FINISHED | E11: UC CHRISTUS - CECA | F11: N/A | G11: mantencion completa de rack ccp y perifericos de ambos linac, se realiza backup mediante acronis de xvi e iview (infinity y axesse) limpieza profunda de estaciones Monaco y Mosaiq ubicadas en dosimetria y sala fisica | H11: https://mail.google.com/mail?extsrc=sync&client=docs&plid=ACUX6DO7fUFGu0eZZfNNAaZO_TQk9mOBGF9PGSw
A12: 46045.855 | B12: 3485 | C12: 9835 | D12: FINISHED | E12: Instituto Nacional del Cáncer (INC) | F12: INC-156473 | G12: Se asiste a sitio a hora acordada y se espera a termino de pacientes, se verifica e inspecciona movimiento del panel encontrandose que a mitad de camino pierde el middle position para retraer, se calibra mediante software y sin resultados positivos, se revisa cadena de switch encontrandose activo al momento de retraer (posicion normal) al retraer pierde posicion y entra en loop de busqueda, se graba video de falla y se consultara a elekta. | H12: https://mail.google.com/mail?extsrc=sync&client=docs&plid=ACUX6DNIUwThTUHE0reAC6nTH8zOdXTI887E-Aw
A13: 46045.68 | B13: 3484 | C13: Tarea Sin Ticket | D13: FINISHED | E13: CLÍNICA SANATORIO ALEMÁN (ONCORAD) | F13: Linac-201110 | G13: Ajuste Centrado Mesa Compact | H13: https://mail.google.com/mail?extsrc=sync&client=docs&plid=ACUX6DOZwMPNGNCDW-DLAh4PV7Vhr1L592sIu6M
A14: 46043.929 | B14: 3483 | C14: 9819 | D14: FINISHED | E14: UC CHRISTUS - SCA | F14: N/A | G14: mantencion rack ccp, iview, xvi, tps | H14: https://mail.google.com/mail?extsrc=sync&client=docs&plid=ACUX6DM3uG8sZMb7Htqg32buYSB6gJbHBbQChg4
A15: 46044.615 | B15: 3482 | C15: 9822 | D15: FINISHED | E15: Instituto Nacional del Cáncer (INC) | F15: N/A | G15: se realiza inspeccion de lo reportado por fisica medica, se puede observar una incrogruencia con lo irradiado y el campo corformado, se realiza la investigacion correspondiente y se determina que el equipo requiere calibracion de los perfiles del haz de luz para buscar la mejor manera de centrar el haz de radiacion y poder ajustar los perfiles del campo. | H15: https://mail.google.com/mail?extsrc=sync&client=docs&plid=ACUX6DOjrVlfp0ZzZMmXDNQRw9UDOVZZtTD7lwg
A16: 46045.383 | B16: 3481 | C16: 9822 | D16: FINISHED | E16: Instituto Nacional del Cáncer (INC) | F16: INC-156473 | G16: Ajuste de perfiles energéticos | H16: https://mail.google.com/mail?extsrc=sync&client=docs&plid=ACUX6DMFQY8PjCdtSoVoFrJ_mho5bWrodgdct1U
A17: 46042.584 | B17: 3479 | C17: 9821 | D17: FINISHED | E17: INRAD | F17: Linac-201172 | G17: Se reemplazó Thyratron, por estar esta en préstamo. Se realiza acondicionamiento. Se realiza QA por físico, con resultados satisfactorios. | H17: https://mail.google.com/mail?extsrc=sync&client=docs&plid=ACUX6DOgQJKFITh2prbntKvElDBwMjsFAO-etvA
A18: 46041.536 | B18: 3477 | C18: Tarea Sin Ticket | D18: FINISHED | E18: UC CHRISTUS - CECA | F18: Linac-109374 | G18: se realiza MP linac | H18: https://mail.google.com/mail?extsrc=sync&client=docs&plid=ACUX6DOcTRB-3hroNs8wv9wO7ETTJEdQQDdQ5to
A19: 46043.356 | B19: 3476 | C19: Tarea Sin Ticket | D19: FINISHED | E19: UC CHRISTUS - CECA | F19: Linac-109374 | G19: Asistencia remota por Dose Rate Mon | H19: https://mail.google.com/mail?extsrc=sync&client=docs&plid=ACUX6DOt0HoW-8xzZBxfy_Skk05e2VQCcDg-UIQ
A20: 46041.459 | B20: 3475 | C20: Tarea Sin Ticket | D20: FINISHED | E20: CLINICA ALEMANA DE SANTIAGO | F20: Linac-152171 | G20: Se asiste al sitio para brindar apoyo en la puesta en marcha del equipo. FM realiza controles de QA en horario AM de forma normal. Posteriormente, al volver a revisar el equipo, este se encontraba fuera de servicio debido a un inhibit de "Water Temp", asociada directamente a un problema en el chiller, el cual estaba siendo revisado al momento de la falla. Tras unos minutos, el equipo recupera su funcionamiento normal y se da inicio al tratamiento de pacientes. | H20: https://mail.google.com/mail?extsrc=sync&client=docs&plid=ACUX6DPul1hdND3DzLpwkKc7xk7koSXGDk6zg2k
A21: 46041.356 | B21: 3474 | C21: Tarea Sin Ticket | D21: FINISHED | E21: HOSPITAL CARLOS VAN BUREN (SSVSA) | F21: Linac-154325 | G21: Se efectua chequeo de equipo en conjunto de en conjunto de Fisico Medico, conforme | H21: https://mail.google.com/mail?extsrc=sync&client=docs&plid=ACUX6DPrSOhb6XTBZnu0tSFMMEwvWL1QQnxSIJY
A22: 46041.622 | B22: 3473 | C22: 9816 | D22: FINISHED | E22: Instituto Nacional del Cáncer (INC) | F22: N/A | G22: se realiza inspeccion del sistema xvi por lo reportado por el cliente, al llegar el sistema xvi arroja error 40, se verifica en el manual tecnico de servicio el error y se realiza la investigacion correspondiente del caso, despues de un analisis y seguimiento de falla se logra observar que la tarjeta de control del generador se encontraba dañada, ese corto en la tarjeta tambien ocaciono daño en el filamento del tubo razon por la cual se realizo el cambio, durante el cambio del tubo de Rx se pudo observar una fisura en el cable de HT del catodo del tubo de Rx y por precaucion se realiza el cambio de los cables de HT del tubo de Rx. | H22: https://mail.google.com/mail?extsrc=sync&client=docs&plid=ACUX6DMGooRmPx_q4KtKBevTkiup70hIbVImp2o
A23: 46038.909 | B23: 3472 | C23: 9754 | D23: FINISHED | E23: HOSPITAL CARLOS VAN BUREN (SSVSA) | F23: N/A | G23: traslado de repuesto linac, mantenimiento, cambio de ups y cambio de disco a rtp99. | H23: https://mail.google.com/mail?extsrc=sync&client=docs&plid=ACUX6DO7dmoQHZA0SQU17x8AdbgMzTnzPenCs6o
A24: 46041.361 | B24: 3471 | C24: Tarea Sin Ticket | D24: FINISHED | E24: HOSPITAL CARLOS VAN BUREN (SSVSA) | F24: Linac-154325 | G24: Cambio de GUN | H24: https://mail.google.com/mail?extsrc=sync&client=docs&plid=ACUX6DP2QIe5dj1h1CN3UYsa6cHseXWg-uhqM7s
A25: 46039.644 | B25: 3470 | C25: Tarea Sin Ticket | D25: FINISHED | E25: UC CHRISTUS - CECA | F25: Linac-109374 | G25: MP XVI y iviewGT Se asiste el dia sabado para recalibracion del sistema XVI, se veriica junto a FM y realizando sus pruebas con resultados satisfactorios. | H25: https://mail.google.com/mail?extsrc=sync&client=docs&plid=ACUX6DNn4y35wrRxU1TupT7VImt_RxZNcsghMd0
A26: 46039.644 | B26: 3469 | C26: Tarea Sin Ticket | D26: FINISHED | E26: UC CHRISTUS - CECA | F26: Linac-109374 | G26: Se realiza MP Linac | H26: https://mail.google.com/mail?extsrc=sync&client=docs&plid=ACUX6DMWkHX0jx07TZSnGGOX4sW5MJA-TQGiydY
A27: 46041.361 | B27: 3467 | C27: Tarea Sin Ticket | D27: FINISHED | E27: HOSPITAL CARLOS VAN BUREN (SSVSA) | F27: Linac-154325 | G27: Mantenimiento Preventivo | H27: https://mail.google.com/mail?extsrc=sync&client=docs&plid=ACUX6DOg4lj4ggiQ_ySUjJRNw1jQQgZqo0W-C-I
A28: 46037.847 | B28: 3464 | C28: 9813 | D28: FINISHED | E28: Instituto Nacional del Cáncer (INC) | F28: INC-156473 | G28: Se asiste a sitio por inhibit Gantry stop, una vez entregado el equipo se efectuan pruebas notando perdida de fuerza en sentido de giro CCW, se revisa ajuste de correas y tension, lo cual se corrije, se verifica gearbox con nivel y se ajusta. Se realizan pruebas con resultados satisfactorios, se entrega equipo a FM el cual realiza sus pruebas correspondientes con resultados ok | H28: https://mail.google.com/mail?extsrc=sync&client=docs&plid=ACUX6DMcRfWLHPslhWTseuvSutsuT-O3rYLplG4
A29: 46036.763 | B29: 3463 | C29: 9810 | D29: FINISHED | E29: CLÍNICA SANATORIO ALEMÁN (ONCORAD) | F29: Linac-201110 | G29: FALLA REVERSE CURRENT EQUIPO COMPACT | H29: https://mail.google.com/mail?extsrc=sync&client=docs&plid=ACUX6DPT0Mfz29PCO4VJ1SRBJwr7qJ0mej0Eaew
A30: 46037.449 | B30: 3462 | C30: 9806 | D30: FINISHED | E30: UC CHRISTUS - SCA | F30: Linac-109256 | G30: Calibración Exapod y Limpieza Agility | H30: https://mail.google.com/mail?extsrc=sync&client=docs&plid=ACUX6DMCvouHBjyCM36_7UNK8KGM2KXeJerlRIM
A31: 46034.44 | B31: 3461 | C31: Tarea Sin Ticket | D31: FINISHED | E31: CLÍNICA SANATORIO ALEMÁN (ONCORAD) | F31: N/A | G31: Eliminación de Usuarios Equipo Compact | H31: https://mail.google.com/mail?extsrc=sync&client=docs&plid=ACUX6DPBIrgjXKBE1Xjdpa2e2dGLZRNdXsPCQWc
A32: 46034.378 | B32: 3460 | C32: Tarea Sin Ticket | D32: FINISHED | E32: CLINICA ALEMANA DE SANTIAGO | F32: Linac-152171 | G32: se acompaña a FM en puesta en marcha estando todo ok en el equipo, ademas, se realizan pruebas diarias estando todo ok | H32: https://mail.google.com/mail?extsrc=sync&client=docs&plid=ACUX6DMkgyhadZUSGnk1_j_miSoaHrYPtpP232U
A33: 46030.823 | B33: 3459 | C33: 9801 | D33: FINISHED | E33: Instituto Nacional del Cáncer (INC) | F33: N/A | G33: se realiza verificacion de los motores pancake, se logra observar que las correas de los motores se encuentran un poco floja, se realiza el ajuste y tension de la correa, se realiza un learning del sitema de posicionamiento y se realiza pruebas de tratamientos VMAT en modo servicio | H33: https://mail.google.com/mail?extsrc=sync&client=docs&plid=ACUX6DN3IAkvAuJWE0qp5uO0D-Com7vtUFHRGQk
A34: 46030.734 | B34: 3458 | C34: 9790 | D34: FINISHED | E34: CLÍNICA SANATORIO ALEMÁN (ONCORAD) | F34: Linac-201110 | G34: Ajuste Telemetro Equipo Compact | H34: https://mail.google.com/mail?extsrc=sync&client=docs&plid=ACUX6DMp9Et7b6gjfaV5STHEQwbXKT4oWJqY7Kg
A35: 46029.48 | B35: 3457 | C35: Tarea Sin Ticket | D35: FINISHED | E35: HOSPITAL CARLOS VAN BUREN (SSVSA) | F35: Linac-154325 | G35: Se efectua Optimizacion de energía 6FFF , vía remota, posteriormente FM efectua control dosimetrico con resultados conforme. | H35: https://mail.google.com/mail?extsrc=sync&client=docs&plid=ACUX6DN6m8WMAr-VmJm444cVDRv95aEW2Nf1M-Q
A36: 46029.631 | B36: 3456 | C36: 9694 | D36: FINISHED | E36: CLINICA ALEMANA DE SANTIAGO | F36: N/A | G36: se realiza el cambio del cable XVI del versa norte ya que presentaba fallas de reconstruccion cuando se realizaba un cbct,la falla se debia a uncabke cortado el cual fue sustituido por uno nuevo. | H36: https://mail.google.com/mail?extsrc=sync&client=docs&plid=ACUX6DMiDny5GVJMqs1IZbDUgtRwZ14fpZ6BblQ
A37: 46027.745 | B37: 3455 | C37: 9793 | D37: FINISHED | E37: CLÍNICA SANATORIO ALEMÁN (ONCORAD) | F37: Linac-201110 | G37: Revisión conexión Cámara Iview Compact | H37: https://mail.google.com/mail?extsrc=sync&client=docs&plid=ACUX6DP3-0uF3xKbsV4zByxTNwl-OrFdaR7JXPs
A38: 46029.479 | B38: 3454 | C38: 9789 | D38: FINISHED | E38: CLINICA ALEMANA DE SANTIAGO | F38: Linac-152171 | G38: Se realizó cambio de 8 fuentes de poder de los KVM del TCS por corto circuito | H38: https://mail.google.com/mail?extsrc=sync&client=docs&plid=ACUX6DOR_V3v2vu7SXc4FwRr_eGfWtozCglpoOo
A39: 46027.518 | B39: 3453 | C39: 9781 | D39: FINISHED | E39: INRAD | F39: N/A | G39: Se realiza el cambio de Thyratron. Thyratron usado (Oncorad). Se realiza ajustes de frecuencias ok. Se efectúa QA conforme. | H39: https://mail.google.com/mail?extsrc=sync&client=docs&plid=ACUX6DMJWJDVqkgv3UvnN-c1Qz1_gFeqvvowAOA
A40: 46027.417 | B40: 3452 | C40: 9790 | D40: FINISHED | E40: CLÍNICA SANATORIO ALEMÁN (ONCORAD) | F40: Linac-201110 | G40: Cambio de Ampolleta Telemetro Compact | H40: https://mail.google.com/mail?extsrc=sync&client=docs&plid=ACUX6DPLLvYEnXE-bSV6fEQQF9K8McPqwCfDVjs
...

Sheet DB_Tickets_Zendesk
A1: Ticket ID | B1: Asunto | C1: Estado | D1: Prioridad | E1: Tipo | F1: Creado (Fecha) | G1: Actualizado (Fecha) | H1: ID Organización | I1: ID Solicitante | J1: ID Técnico | K1: Tags | L1: Custom Fields (JSON Dump)
A2: 9821 | B2: solicitud cambio de thyratron | C2: pending | D2: urgent | E2: incident | F2: 46042.448 | G2: 46042.484 | H2: 14742026913435 | I2: 38368479928987 | K2: acelerador_lineal, braquiterapia, compact, elekta, hardware_y_software, monaco, monacosim, mosaiq, no, requerimiento, tcs, xio | L2: [{"id":22950764862363,"value":null},{"id":22951106310811,"value":"acelerador_lineal"},{"id":22986688179995,"value":"no"},{"id":23570126394907,"value":"requerimiento"},{"id":34267608050075,"value":"tcs"},{"id":39065204608155,"value":null},{"id":40011436329115,"value":"01K2MXCF9WW205P1YQ3PCD50A9"},{"id":43011722643739,"value":null},{"id":43806479792155,"value":null},{"id":43806495652507,"value":null}]
A3: 9817 | B3: Solicitud de conexión para el TRM | C3: pending | D3: low | E3: incident | F3: 46041.52 | G3: 46041.522 | H3: 14741543428379 | I3: 26132276827035 | J3: 14481448391451 | K3: elekta, hardware_y_software, hexapod, iview, linac, monaco, mosaiq, no, platform, requerimiento, suncheck, suncheck_machine, sunnuclear, tens, versahd, xvi | L3: [{"id":22950764862363,"value":null},{"id":22951106310811,"value":"suncheck"},{"id":22986688179995,"value":"no"},{"id":23570126394907,"value":"requerimiento"},{"id":34267608050075,"value":null},{"id":39065204608155,"value":null},{"id":40011436329115,"value":"01K2MWPZ0X0DMAW9P42PW6X6V4"},{"id":43011722643739,"value":null},{"id":43806479792155,"value":null},{"id":43806495652507,"value":null}]
A4: 9816 | B4: Falla del tubo de rayos X | C4: new | D4: urgent | E4: incident | F4: 46037.638 | G4: 46037.642 | H4: 14741593614363 | I4: 35062929091611 | K4: citrix, elekta, hardware_y_software, infinity, integrity, iview, linac, media, monaco, mosaiq, problema, si, storage, suncheck_machine, sunnuclear, xvi | L4: [{"id":22950764862363,"value":null},{"id":22951106310811,"value":"integrity"},{"id":22986688179995,"value":"si"},{"id":23570126394907,"value":"problema"},{"id":34267608050075,"value":null},{"id":39065204608155,"value":null},{"id":40011436329115,"value":"01K2MWR2KCZK72HY0ZV2CSMFTN"},{"id":43011722643739,"value":null},{"id":43806479792155,"value":null},{"id":43806495652507,"value":null}]
A5: 9812 | B5: Table long | C5: solved | D5: high | E5: incident | F5: 46036.584 | G5: 46037.668 | H5: 14741543428379 | I5: 26080982926747 | J5: 19579468718875 | K5: elekta, físico, hardware_y_software, hexapod, iview, linac, monaco, mosaiq, no, platform, problema, sistema_camilla_precise, suncheck_machine, sunnuclear, versahd, xvi | L5: [{"id":22950764862363,"value":null},{"id":22951106310811,"value":"sistema_camilla_precise"},{"id":22986688179995,"value":"no"},{"id":23570126394907,"value":"problema"},{"id":34267608050075,"value":null},{"id":39065204608155,"value":null},{"id":40011436329115,"value":"01K2MWPZ0X0DMAW9P42PW6X6V4"},{"id":43011722643739,"value":null},{"id":43806479792155,"value":null},{"id":43806495652507,"value":null}]
A6: 9811 | B6: Se solicita calibración de láseres de sala de equipo Versa | C6: new | D6: high | E6: incident | F6: 46036.544 | G6: 46036.544 | H6: 14741318546075 | I6: 36182421530907 | K6: agility, elekta, hardware_y_software, monaco, mosaiq, no, requerimiento, sinergy, suncheck, suncheck_machine, sunnuclear, supervisor_de_equipo_médicos, versahd | L6: [{"id":22950764862363,"value":null},{"id":22951106310811,"value":"suncheck"},{"id":22986688179995,"value":"no"},{"id":23570126394907,"value":"requerimiento"},{"id":34267608050075,"value":null},{"id":39065204608155,"value":null},{"id":40011436329115,"value":"01K2MWKNK7SBBFQAXJYFH5C7RR"},{"id":43011722643739,"value":null},{"id":43806479792155,"value":null},{"id":43806495652507,"value":null}]
A7: 9809 | B7: Panel iview | C7: open | D7: normal | E7: incident | F7: 46036.448 | G7: 46037.45 | H7: 14741543428379 | I7: 26080982926747 | K7: elekta, físico, hardware_y_software, hexapod, iview, linac, monaco, mosaiq, no, platform, problema, sistema_de_imagen_portal_iview, suncheck_machine, sunnuclear, versahd, xvi | L7: [{"id":22950764862363,"value":null},{"id":22951106310811,"value":"sistema_de_imagen_portal_iview"},{"id":22986688179995,"value":"no"},{"id":23570126394907,"value":"problema"},{"id":34267608050075,"value":null},{"id":39065204608155,"value":null},{"id":40011436329115,"value":"01K2MWPZ0X0DMAW9P42PW6X6V4"},{"id":43011722643739,"value":null},{"id":43806479792155,"value":null},{"id":43806495652507,"value":null}]
A8: 9809 | B8: Panel iview | C8: open | D8: normal | E8: incident | F8: 46036.448 | G8: 46042.445 | H8: 14741543428379 | I8: 26080982926747 | K8: elekta, físico, hardware_y_software, hexapod, iview, linac, monaco, mosaiq, no, platform, problema, sistema_de_imagen_portal_iview, suncheck_machine, sunnuclear, versahd, xvi | L8: [{"id":22950764862363,"value":null},{"id":22951106310811,"value":"sistema_de_imagen_portal_iview"},{"id":22986688179995,"value":"no"},{"id":23570126394907,"value":"problema"},{"id":34267608050075,"value":null},{"id":39065204608155,"value":null},{"id":40011436329115,"value":"01K2MWPZ0X0DMAW9P42PW6X6V4"},{"id":43011722643739,"value":null},{"id":43806479792155,"value":null},{"id":43806495652507,"value":null}]
A9: 9807 | B9: Equipo no logra iniciar | C9: solved | D9: high | E9: incident | F9: 46035.465 | G9: 46037.501 | H9: 14741318546075 | I9: 36182421530907 | J9: 22297930568347 | K9: agility, elekta, hardware_y_software, monaco, mosaiq, problema, si, sinergy, suncheck, suncheck_machine, sunnuclear, supervisor_de_equipo_médicos, versahd | L9: [{"id":22950764862363,"value":null},{"id":22951106310811,"value":"suncheck"},{"id":22986688179995,"value":"si"},{"id":23570126394907,"value":"problema"},{"id":34267608050075,"value":null},{"id":39065204608155,"value":null},{"id":40011436329115,"value":"01K2MWKNK7SBBFQAXJYFH5C7RR"},{"id":43011722643739,"value":null},{"id":43806479792155,"value":null},{"id":43806495652507,"value":null}]
A10: 9807 | B10: Equipo no logra iniciar | C10: closed | D10: high | E10: incident | F10: 46035.465 | G10: 46040.518 | H10: 14741318546075 | I10: 36182421530907 | J10: 22297930568347 | K10: agility, elekta, hardware_y_software, monaco, mosaiq, problema, si, sinergy, suncheck, suncheck_machine, sunnuclear, supervisor_de_equipo_médicos, versahd | L10: [{"id":22950764862363,"value":null},{"id":22951106310811,"value":"suncheck"},{"id":22986688179995,"value":"si"},{"id":23570126394907,"value":"problema"},{"id":34267608050075,"value":null},{"id":39065204608155,"value":null},{"id":40011436329115,"value":"01K2MWKNK7SBBFQAXJYFH5C7RR"},{"id":43011722643739,"value":null},{"id":43806479792155,"value":null},{"id":43806495652507,"value":null}]
A11: 9806 | B11: Interlock PRF En Chk | C11: pending | D11: high | E11: incident | F11: 46034.977 | G11: 46037.643 | H11: 20265216319003 | I11: 20254050952987 | K11: axesse, barcoding, braquiterapia, dosisoft, elekta, físico, hardware_y_software, infinity, iview, linac, monaco, monacosim, mosaiq, no, problema, storage, versahd, xvi | L11: [{"id":22950764862363,"value":null},{"id":22951106310811,"value":"dosisoft"},{"id":22986688179995,"value":"no"},{"id":23570126394907,"value":"problema"},{"id":34267608050075,"value":null},{"id":39065204608155,"value":null},{"id":40011436329115,"value":"01K2MWGQVK5P8BZ4P54MS8055Q"},{"id":43011722643739,"value":null},{"id":43806479792155,"value":null},{"id":43806495652507,"value":null}]
A12: 9805 | B12: System on water temp | C12: solved | D12: high | E12: incident | F12: 46034.468 | G12: 46036.751 | H12: 14741543428379 | I12: 26080982926747 | J12: 19579468718875 | K12: elekta, físico, hardware_y_software, hexapod, iview, linac, monaco, mosaiq, no, platform, problema, suncheck, suncheck_machine, sunnuclear, versahd, xvi | L12: [{"id":22950764862363,"value":null},{"id":22951106310811,"value":"suncheck"},{"id":22986688179995,"value":"no"},{"id":23570126394907,"value":"problema"},{"id":34267608050075,"value":null},{"id":39065204608155,"value":null},{"id":40011436329115,"value":"01K2MWPZ0X0DMAW9P42PW6X6V4"},{"id":43011722643739,"value":null},{"id":43806479792155,"value":null},{"id":43806495652507,"value":null}]
A13: 9804 | B13: Calibración hexapod | C13: solved | D13: high | E13: incident | F13: 46031.721 | G13: 46037.629 | H13: 20265216319003 | I13: 20254050952987 | J13: 22297930568347 | K13: axesse, barcoding, braquiterapia, dosisoft, elekta, físico, hardware_y_software, infinity, iview, linac, monaco, monacosim, mosaiq, no, problema, storage, versahd, xvi | L13: [{"id":22950764862363,"value":null},{"id":22951106310811,"value":"dosisoft"},{"id":22986688179995,"value":"no"},{"id":23570126394907,"value":"problema"},{"id":34267608050075,"value":null},{"id":39065204608155,"value":null},{"id":40011436329115,"value":"01K2MWGQVK5P8BZ4P54MS8055Q"},{"id":43011722643739,"value":null},{"id":43806479792155,"value":null},{"id":43806495652507,"value":null}]
A14: 9804 | B14: Calibración hexapod | C14: solved | D14: high | E14: incident | F14: 46031.721 | G14: 46039.656 | H14: 20265216319003 | I14: 20254050952987 | J14: 22297930568347 | K14: axesse, barcoding, braquiterapia, dosisoft, elekta, físico, hardware_y_software, infinity, iview, linac, monaco, monacosim, mosaiq, no, problema, storage, versahd, xvi | L14: [{"id":22950764862363,"value":null},{"id":22951106310811,"value":"dosisoft"},{"id":22986688179995,"value":"no"},{"id":23570126394907,"value":"problema"},{"id":34267608050075,"value":null},{"id":39065204608155,"value":null},{"id":40011436329115,"value":"01K2MWGQVK5P8BZ4P54MS8055Q"},{"id":43011722643739,"value":null},{"id":43806479792155,"value":null},{"id":43806495652507,"value":null}]
A15: 9801 | B15: Gantry Stop-Infinity detenido - se requiere atencion en terreno lo antes posible | C15: closed | D15: urgent | E15: incident | F15: 46030.804 | G15: 46035.561 | H15: 14741593614363 | I15: 20254050947483 | J15: 22297930568347 | K15: citrix, elekta, físico, hardware_y_software, infinity, integrity, iview, linac, media, monaco, mosaiq, problema, si, storage, suncheck_machine, sunnuclear, xvi | L15: [{"id":22950764862363,"value":null},{"id":22951106310811,"value":"integrity"},{"id":22986688179995,"value":"si"},{"id":23570126394907,"value":"problema"},{"id":34267608050075,"value":null},{"id":39065204608155,"value":null},{"id":40011436329115,"value":"01K2MWR2KCZK72HY0ZV2CSMFTN"},{"id":43011722643739,"value":null},{"id":43806479792155,"value":null},{"id":43806495652507,"value":null}]
A16: 9800 | B16: Solicitud de actualizacion de licencias productos Sunnuclear | C16: new | D16: urgent | E16: incident | F16: 46030.601 | G16: 46030.601 | H16: 14741593614363 | I16: 20254050948123 | K16: citrix, elekta, físico, hardware_y_software, infinity, integrity, iview, linac, media, monaco, mosaiq, no, problema, storage, suncheck_machine, sunnuclear, xvi | L16: [{"id":22950764862363,"value":null},{"id":22951106310811,"value":"integrity"},{"id":22986688179995,"value":"no"},{"id":23570126394907,"value":"problema"},{"id":34267608050075,"value":null},{"id":39065204608155,"value":null},{"id":40011436329115,"value":"01K2MWR2KCZK72HY0ZV2CSMFTN"},{"id":43011722643739,"value":null},{"id":43806479792155,"value":null},{"id":43806495652507,"value":null}]
A17: 9799 | B17: Interlocks MLC VERSA 1 | C17: solved | D17: high | E17: incident | F17: 46029.469 | G17: 46037.501 | H17: 14741389938587 | I17: 20254020292379 | J17: 22297930568347 | K17: abc, elekta, físico, hardware_y_software, hexapod, media, monaco, mosaiq, no, problema, versahd | L17: [{"id":22950764862363,"value":null},{"id":22951106310811,"value":"abc"},{"id":22986688179995,"value":"no"},{"id":23570126394907,"value":"problema"},{"id":34267608050075,"value":null},{"id":39065204608155,"value":null},{"id":40011436329115,"value":"01K2MWVQJ3DHXN1BYF1WF54DC4"},{"id":43011722643739,"value":null},{"id":43806479792155,"value":null},{"id":43806495652507,"value":null}]
A18: 9799 | B18: Interlocks MLC VERSA 1 | C18: closed | D18: high | E18: incident | F18: 46029.469 | G18: 46040.518 | H18: 14741389938587 | I18: 20254020292379 | J18: 22297930568347 | K18: abc, elekta, físico, hardware_y_software, hexapod, media, monaco, mosaiq, no, problema, versahd | L18: [{"id":22950764862363,"value":null},{"id":22951106310811,"value":"abc"},{"id":22986688179995,"value":"no"},{"id":23570126394907,"value":"problema"},{"id":34267608050075,"value":null},{"id":39065204608155,"value":null},{"id":40011436329115,"value":"01K2MWVQJ3DHXN1BYF1WF54DC4"},{"id":43011722643739,"value":null},{"id":43806479792155,"value":null},{"id":43806495652507,"value":null}]
A19: 9796 | B19: Gantry Stop aleatorio en CL2 Infinity | C19: closed | D19: urgent | E19: incident | F19: 46028.564 | G19: 46035.561 | H19: 14741593614363 | I19: 20254050947483 | J19: 22297930568347 | K19: citrix, elekta, físico, hardware_y_software, infinity, integrity, iview, linac, media, monaco, mosaiq, no, problema, storage, suncheck_machine, sunnuclear, xvi | L19: [{"id":22950764862363,"value":null},{"id":22951106310811,"value":"integrity"},{"id":22986688179995,"value":"no"},{"id":23570126394907,"value":"problema"},{"id":34267608050075,"value":null},{"id":39065204608155,"value":null},{"id":40011436329115,"value":"01K2MWR2KCZK72HY0ZV2CSMFTN"},{"id":43011722643739,"value":null},{"id":43806479792155,"value":null},{"id":43806495652507,"value":null}]
A20: 9795 | B20: Infinity se apaga solo | C20: new | D20: urgent | E20: incident | F20: 46028.478 | G20: 46028.478 | H20: 14741593614363 | I20: 20254050947483 | K20: citrix, elekta, físico, hardware_y_software, infinity, integrity, iview, linac, media, monaco, mosaiq, no, problema, storage, suncheck_machine, sunnuclear, xvi | L20: [{"id":22950764862363,"value":null},{"id":22951106310811,"value":"integrity"},{"id":22986688179995,"value":"no"},{"id":23570126394907,"value":"problema"},{"id":34267608050075,"value":null},{"id":39065204608155,"value":null},{"id":40011436329115,"value":"01K2MWR2KCZK72HY0ZV2CSMFTN"},{"id":43011722643739,"value":null},{"id":43806479792155,"value":null},{"id":43806495652507,"value":null}]
A21: 9792 | B21: Perdida conexión Axesse | C21: new | D21: normal | E21: incident | F21: 46027.589 | G21: 46027.589 | H21: 14741297259931 | I21: 23562920769947 | K21: axesse, braquiterapia, clarity, elekta, físico, hardware_y_software, infinity, monaco, mosaiq, no, problema | L21: [{"id":22950764862363,"value":null},{"id":22951106310811,"value":"clarity"},{"id":22986688179995,"value":"no"},{"id":23570126394907,"value":"problema"},{"id":34267608050075,"value":null},{"id":39065204608155,"value":null},{"id":40011436329115,"value":"01K2MVY8Y64ADSZN89S82WQWXZ"},{"id":43011722643739,"value":null},{"id":43806479792155,"value":null},{"id":43806495652507,"value":null}]
A22: 9785 | B22: Maquina se reinicia sola | C22: closed | D22: normal | E22: incident | F22: 46021.599 | G22: 46032.691 | H22: 14741543428379 | I22: 26080982926747 | J22: 19579468718875 | K22: acelerador_lineal, elekta, físico, hardware_y_software, hexapod, iview, linac, monaco, mosaiq, no, platform, problema, suncheck_machine, sunnuclear, versahd, xvi | L22: [{"id":22950764862363,"value":null},{"id":22951106310811,"value":"acelerador_lineal"},{"id":22986688179995,"value":"no"},{"id":23570126394907,"value":"problema"},{"id":34267608050075,"value":null},{"id":39065204608155,"value":null},{"id":40011436329115,"value":"01K2MWPZ0X0DMAW9P42PW6X6V4"},{"id":43011722643739,"value":null},{"id":43806479792155,"value":null},{"id":43806495652507,"value":null}]
A23: 9783 | B23: advertencia Replace Filter - SunSCAN | C23: pending | D23: high | E23: incident | F23: 46021.533 | G23: 46029.793 | H23: 14741593614363 | I23: 20254050947483 | J23: 14734559344539 | K23: citrix, elekta, físico, hardware_y_software, infinity, iview, linac, media, monaco, mosaiq, no, on_hold_1h, problema, storage, suncheck, suncheck_machine, sunnuclear, xvi | L23: [{"id":22950764862363,"value":null},{"id":22951106310811,"value":"suncheck"},{"id":22986688179995,"value":"no"},{"id":23570126394907,"value":"problema"},{"id":34267608050075,"value":null},{"id":39065204608155,"value":null},{"id":40011436329115,"value":"01K2MWR2KCZK72HY0ZV2CSMFTN"},{"id":43011722643739,"value":null},{"id":43806479792155,"value":null},{"id":43806495652507,"value":null}]
A24: 9782 | B24: falla humidificador y AACC del bunker del Infinity | C24: closed | D24: low | E24: incident | F24: 46021.512 | G24: 46028.724 | H24: 14741593614363 | I24: 20254050947483 | J24: 19579474867355 | K24: acelerador_lineal, elekta, físico, linac, no, problema | L24: [{"id":22950764862363,"value":null},{"id":22951106310811,"value":"acelerador_lineal"},{"id":22986688179995,"value":"no"},{"id":23570126394907,"value":"problema"},{"id":34267608050075,"value":null},{"id":39065204608155,"value":null},{"id":40011436329115,"value":"01K2MWR2KCZK72HY0ZV2CSMFTN"},{"id":43011722643739,"value":null},{"id":43806479792155,"value":null},{"id":43806495652507,"value":null}]
A25: 9781 | B25: Equipo detenido por Problema con "Tasa de dosis baja Canal A" y B | C25: solved | D25: urgent | E25: incident | F25: 46020.746 | G25: 46037.633 | H25: 14742026913435 | I25: 38368479928987 | J25: 22297930568347 | K25: acelerador_lineal, braquiterapia, compact, elekta, hardware_y_software, monaco, monacosim, mosaiq, requerimiento, si, tcs, xio | L25: [{"id":22950764862363,"value":null},{"id":22951106310811,"value":"acelerador_lineal"},{"id":22986688179995,"value":"si"},{"id":23570126394907,"value":"requerimiento"},{"id":34267608050075,"value":"tcs"},{"id":39065204608155,"value":null},{"id":40011436329115,"value":"01K2MXCF9WW205P1YQ3PCD50A9"},{"id":43011722643739,"value":null},{"id":43806479792155,"value":null},{"id":43806495652507,"value":null}]
A26: 9778 | B26: Reaparición falla “Gantry Stop” – CL02 Infinity / Ticket 9774 | C26: closed | D26: urgent | E26: incident | F26: 46020.709 | G26: 46032.607 | H26: 14741593614363 | I26: 20254050947483 | J26: 19579474867355 | K26: acelerador_lineal, elekta, físico, hardware_y_software, infinity, linac, no, problema | L26: [{"id":22950764862363,"value":null},{"id":22951106310811,"value":"acelerador_lineal"},{"id":22986688179995,"value":"no"},{"id":23570126394907,"value":"problema"},{"id":34267608050075,"value":null},{"id":39065204608155,"value":null},{"id":40011436329115,"value":"01K2MWR2KCZK72HY0ZV2CSMFTN"},{"id":43011722643739,"value":null},{"id":43806479792155,"value":null},{"id":43806495652507,"value":null}]
A27: 9775 | B27: DOSE RATE MON 6MeV INFINITY | C27: closed | D27: normal | E27: incident | F27: 46015.737 | G27: 46024.614 | H27: 14741297259931 | I27: 20254050952347 | J27: 19579474867355 | K27: acelerador_lineal, elekta, físico, infinity, no, problema | L27: [{"id":22950764862363,"value":null},{"id":22951106310811,"value":"acelerador_lineal"},{"id":22986688179995,"value":"no"},{"id":23570126394907,"value":"problema"},{"id":34267608050075,"value":null},{"id":39065204608155,"value":null},{"id":40011436329115,"value":"01K2MWEACAGHS4HXG14TE1Y3QE"},{"id":43011722643739,"value":null},{"id":43806479792155,"value":null},{"id":43806495652507,"value":null}]
A28: 9774 | B28: falla Gantry Stop - no puedo hacer QA de paciente - Equipo detenido | C28: closed | D28: urgent | E28: incident | F28: 46015.736 | G28: 46019.908 | H28: 14741593614363 | I28: 20254050947483 | J28: 20210900681499 | K28: citrix, elekta, físico, hardware_y_software, infinity, integrity, iview, linac, media, monaco, mosaiq, problema, si, storage, suncheck_machine, sunnuclear, xvi | L28: [{"id":22950764862363,"value":null},{"id":22951106310811,"value":"integrity"},{"id":22986688179995,"value":"si"},{"id":23570126394907,"value":"problema"},{"id":34267608050075,"value":null},{"id":39065204608155,"value":null},{"id":40011436329115,"value":"01K2MWR2KCZK72HY0ZV2CSMFTN"},{"id":43011722643739,"value":null},{"id":43806479792155,"value":null},{"id":43806495652507,"value":null}]
A29: 9770 | B29: Water Temp | C29: closed | D29: urgent | E29: incident | F29: 46013.655 | G29: 46033.618 | H29: 20265216319003 | I29: 20254050953243 | J29: 20210900681499 | K29: axesse, barcoding, braquiterapia, dosisoft, elekta, físico, hardware_y_software, infinity, iview, linac, monaco, monacosim, mosaiq, problema, si, storage, versahd, xvi | L29: [{"id":22950764862363,"value":null},{"id":22951106310811,"value":"dosisoft"},{"id":22986688179995,"value":"si"},{"id":23570126394907,"value":"problema"},{"id":34267608050075,"value":null},{"id":39065204608155,"value":null},{"id":40011436329115,"value":"01K2MWGQVK5P8BZ4P54MS8055Q"},{"id":43011722643739,"value":null},{"id":43806479792155,"value":null},{"id":43806495652507,"value":null}]
A30: 9764 | B30: Multiples interlocks mas charco de agua en sala de maquinas de origen desconocido | C30: closed | D30: urgent | E30: incident | F30: 46010.494 | G30: 46017.642 | H30: 14741389938587 | I30: 20254020292379 | J30: 19579474867355 | K30: acelerador_lineal, elekta, físico, hexapod, problema, si, versahd | L30: [{"id":22950764862363,"value":null},{"id":22951106310811,"value":"acelerador_lineal"},{"id":22986688179995,"value":"si"},{"id":23570126394907,"value":"problema"},{"id":34267608050075,"value":null},{"id":39065204608155,"value":null},{"id":40011436329115,"value":"01K2MWVQJ3DHXN1BYF1WF54DC4"},{"id":43011722643739,"value":null},{"id":43806479792155,"value":null},{"id":43806495652507,"value":null}]
A31: 9762 | B31: Solicitud de MP Flexitro | C31: new | D31: normal | E31: incident | F31: 46009.542 | G31: 46036.634 | H31: 14741297259931 | I31: 20254050952347 | K31: axesse, braquiterapia, clarity, elekta, flexitron, físico, hardware_y_software, infinity, monaco, mosaiq, no, requerimiento | L31: [{"id":22950764862363,"value":null},{"id":22951106310811,"value":"clarity"},{"id":22986688179995,"value":"no"},{"id":23570126394907,"value":"requerimiento"},{"id":34267608050075,"value":"flexitron"},{"id":39065204608155,"value":null},{"id":40011436329115,"value":null},{"id":43011722643739,"value":null},{"id":43806479792155,"value":null},{"id":43806495652507,"value":null}]
A32: 9751 | B32: Table long | C32: closed | E32: incident | F32: 46006.519 | G32: 46006.86 | H32: 14741543428379 | I32: 26080982926747 | J32: 19579468718875 | K32: closed_by_merge, elekta, físico, hardware_y_software, hexapod, iview, linac, monaco, mosaiq, platform, suncheck, suncheck_machine, sunnuclear, versahd, xvi | L32: [{"id":22950764862363,"value":null},{"id":22951106310811,"value":"suncheck"},{"id":22986688179995,"value":null},{"id":23570126394907,"value":null},{"id":34267608050075,"value":null},{"id":39065204608155,"value":null},{"id":40011436329115,"value":null},{"id":43011722643739,"value":null},{"id":43806479792155,"value":null},{"id":43806495652507,"value":null}]
A33: 9749 | B33: Dose rate mon | C33: closed | D33: urgent | E33: incident | F33: 46003.519 | G33: 46011.676 | H33: 14741597726619 | I33: 20254020299291 | J33: 22297930568347 | K33: acelerador_lineal, elekta, físico, hexapod, iview, no, problema, versahd, xvi | L33: [{"id":22950764862363,"value":null},{"id":22951106310811,"value":"acelerador_lineal"},{"id":22986688179995,"value":"no"},{"id":23570126394907,"value":"problema"},{"id":34267608050075,"value":""},{"id":39065204608155,"value":null},{"id":40011436329115,"value":"01K2MWN8SVJSHMJQM7F39XXN01"},{"id":43011722643739,"value":null},{"id":43806479792155,"value":null},{"id":43806495652507,"value":null}]
A34: 9748 | B34: Importación plan respalado | C34: closed | D34: low | E34: incident | F34: 46003.493 | G34: 46017.514 | H34: 14741543428379 | I34: 40109334283675 | J34: 14481448391451 | K34: elekta, hardware_y_software, hexapod, iview, linac, monaco, monaco_tps, mosaiq, no, platform, requerimiento, suncheck_machine, sunnuclear, versahd, xvi | L34: [{"id":22950764862363,"value":null},{"id":22951106310811,"value":"monaco_tps"},{"id":22986688179995,"value":"no"},{"id":23570126394907,"value":"requerimiento"},{"id":34267608050075,"value":null},{"id":39065204608155,"value":null},{"id":40011436329115,"value":"01K2MWPZ0X0DMAW9P42PW6X6V4"},{"id":43011722643739,"value":null},{"id":43806479792155,"value":null},{"id":43806495652507,"value":null}]
A36: 9746 | B36: Panel de control lateral de camilla está suelto | C36: closed | D36: normal | E36: incident | F36: 46002.736 | G36: 46007.663 | H36: 14741543428379 | I36: 26080969273499 | J36: 19579468718875 | K36: elekta, físico, hardware_y_software, hexapod, iview, linac, monaco, mosaiq, no, platform, requerimiento, sistema_camilla_precise, suncheck_machine, sunnuclear, versahd, xvi | L36: [{"id":22950764862363,"value":null},{"id":22951106310811,"value":"sistema_camilla_precise"},{"id":22986688179995,"value":"no"},{"id":23570126394907,"value":"requerimiento"},{"id":34267608050075,"value":null},{"id":39065204608155,"value":null},{"id":40011436329115,"value":"01K2MWPZ0X0DMAW9P42PW6X6V4"},{"id":43011722643739,"value":null},{"id":43806479792155,"value":null},{"id":43806495652507,"value":null}]
A37: 9745 | B37: Interlock Table Long | C37: closed | D37: normal | E37: incident | F37: 46002.626 | G37: 46032.691 | H37: 14741543428379 | I37: 26080969273499 | J37: 19579468718875 | K37: elekta, físico, hardware_y_software, hexapod, iview, linac, monaco, mosaiq, no, platform, problema, sistema_camilla_precise, suncheck_machine, sunnuclear, versahd, xvi | L37: [{"id":22950764862363,"value":null},{"id":22951106310811,"value":"sistema_camilla_precise"},{"id":22986688179995,"value":"no"},{"id":23570126394907,"value":"problema"},{"id":34267608050075,"value":null},{"id":39065204608155,"value":null},{"id":40011436329115,"value":"01K2MWPZ0X0DMAW9P42PW6X6V4"},{"id":43011722643739,"value":null},{"id":43806479792155,"value":null},{"id":43806495652507,"value":null}]
A38: 9743 | B38: Switches sin luz | C38: closed | D38: low | E38: incident | F38: 46002.542 | G38: 46017.514 | H38: 14741543428379 | I38: 26080982926747 | J38: 14481448391451 | K38: elekta, físico, hardware_y_software, hexapod, incidente, iview, linac, monaco, mosaiq, mosaiq_workstation, no, platform, suncheck_machine, sunnuclear, versahd, xvi | L38: [{"id":22950764862363,"value":null},{"id":22951106310811,"value":"mosaiq_workstation"},{"id":22986688179995,"value":"no"},{"id":23570126394907,"value":"incidente"},{"id":34267608050075,"value":null},{"id":39065204608155,"value":null},{"id":40011436329115,"value":"01K2MWPZ0X0DMAW9P42PW6X6V4"},{"id":43011722643739,"value":null},{"id":43806479792155,"value":null},{"id":43806495652507,"value":null}]
A39: 9742 | B39: Conebeam presenta artefacto | C39: closed | D39: high | E39: incident | F39: 46001.851 | G39: 46012.742 | H39: 14741318546075 | I39: 36182421530907 | J39: 20210900681499 | K39: agility, elekta, hardware_y_software, monaco, mosaiq, no, problema, sinergy, suncheck, suncheck_machine, sunnuclear, supervisor_de_equipo_médicos, versahd | L39: [{"id":22950764862363,"value":null},{"id":22951106310811,"value":"suncheck"},{"id":22986688179995,"value":"no"},{"id":23570126394907,"value":"problema"},{"id":34267608050075,"value":null},{"id":39065204608155,"value":null},{"id":40011436329115,"value":"01K2MWKNK7SBBFQAXJYFH5C7RR"},{"id":43011722643739,"value":null},{"id":43806479792155,"value":null},{"id":43806495652507,"value":null}]
A40: 9740 | B40: verificacion configuracion del Baseline del test de Hancock MLC Suncheck del Infinity | C40: open | D40: urgent | E40: incident | F40: 46001.651 | G40: 46028.664 | H40: 14741593614363 | I40: 20254050947483 | J40: 19579474867355 | K40: citrix, elekta, físico, hardware_y_software, infinity, iview, linac, media, monaco, mosaiq, no, on_hold_1h, requerimiento, storage, suncheck_machine, sunnuclear, xvi | L40: [{"id":22950764862363,"value":null},{"id":22951106310811,"value":""},{"id":22986688179995,"value":"no"},{"id":23570126394907,"value":"requerimiento"},{"id":34267608050075,"value":null},{"id":39065204608155,"value":null},{"id":40011436329115,"value":"01K2MWR2KCZK72HY0ZV2CSMFTN"},{"id":43011722643739,"value":null},{"id":43806479792155,"value":null},{"id":43806495652507,"value":null}]
A41: 9740 | B41: verificacion configuracion del Baseline del test de Hancock MLC Suncheck del Infinity | C41: pending | D41: urgent | E41: incident | F41: 46001.651 | G41: 46041.501 | H41: 14741593614363 | I41: 20254050947483 | J41: 19579474867355 | K41: citrix, elekta, físico, hardware_y_software, infinity, iview, linac, media, monaco, mosaiq, no, on_hold_1h, requerimiento, storage, suncheck_machine, sunnuclear, xvi | L41: [{"id":22950764862363,"value":null},{"id":22951106310811,"value":""},{"id":22986688179995,"value":"no"},{"id":23570126394907,"value":"requerimiento"},{"id":34267608050075,"value":null},{"id":39065204608155,"value":null},{"id":40011436329115,"value":"01K2MWR2KCZK72HY0ZV2CSMFTN"},{"id":43011722643739,"value":null},{"id":43806479792155,"value":null},{"id":43806495652507,"value":null}]
...

Sheet Tickets_Data
A1: url | B1: id | C1: {=IF( ISNUMBER(MATCH(B2, Reporte_Tickets_Detallado!C:C, 0)), "Vinculado (" & INDEX(Reporte_Tickets_Detallado!B:B, MATCH(B2, Reporte_Tickets_Detallado!C:C, 0)) & ")", "Sin Tarea" )} -> Sin Tarea | D1: created_at | E1: updated_at | F1: generated_timestamp | G1: type | H1: subject | I1: raw_subject | J1: description | K1: priority | L1: status | M1: requester_id | N1: submitter_id | O1: assignee_id | P1: organization_id | Q1: group_id | R1: has_incidents | S1: is_public | T1: custom_status_id | U1: encoded_id | V1: ticket_form_id | W1: brand_id | X1: allow_channelback | Y1: allow_attachments | Z1: from_messaging_channel | AA1: support_type | AB1: via_channel | AC1: satisfaction_score | AD1: tags_list | AE1: CF_22950764862363 | AF1: CF_22951106310811 | AG1: CF_22986688179995 | AH1: CF_23570126394907 | AI1: CF_34267608050075 | AJ1: CF_39065204608155 | AK1: CF_40011436329115 | AL1: CF_43011722643739 | AM1: CF_43806479792155 | AN1: CF_43806495652507
A2: https://eygmedicalsystems.zendesk.com/api/v2/tickets/9805.json | B2: 9805 | C2: {=IF( ISNUMBER(MATCH(B2, Reporte_Tickets_Detallado!C:C, 0)), "Vinculado (" & INDEX(Reporte_Tickets_Detallado!B:B, MATCH(B2, Reporte_Tickets_Detallado!C:C, 0)) & ")", "Sin Tarea" )} -> Sin Tarea | D2: 46034.468 | E2: 46034.689 | F2: 1768235516 | G2: incident | H2: System on water temp | I2: System on water temp | J2: Maquina cae a system on por water temp | K2: high | L2: new | M2: 26080982926747 | N2: 26080982926747 | P2: 14741543428379 | Q2: 14481465021595 | R2: FALSE | S2: TRUE | T2: 14481427193115 | U2: 7RX32G-PJ479 | V2: 20427286020763 | W2: 14481427110299 | X2: FALSE | Y2: TRUE | Z2: FALSE | AA2: agent | AB2: email | AC2: unoffered | AD2: elekta, físico, hardware_y_software, hexapod, iview, linac, monaco, mosaiq, no, platform, problema, suncheck, suncheck_machine, sunnuclear, versahd, xvi | AF2: suncheck | AG2: no | AH2: problema | AK2: 01K2MWPZ0X0DMAW9P42PW6X6V4
A3: https://eygmedicalsystems.zendesk.com/api/v2/tickets/9804.json | B3: 9804 | C3: {=IF( ISNUMBER(MATCH(B3, Reporte_Tickets_Detallado!C:C, 0)), "Vinculado (" & INDEX(Reporte_Tickets_Detallado!B:B, MATCH(B3, Reporte_Tickets_Detallado!C:C, 0)) & ")", "Sin Tarea" )} -> Sin Tarea | D3: 46031.721 | E3: 46034.753 | F3: 1768241069 | G3: incident | H3: Calibración hexapod | I3: Calibración hexapod | J3: Estimados, Les escribo ya que la prueba diaria de la hexapod esta presentando una desviación respecto a los láseres. Cuando podrían venir para realizar la calibración? Nosotros proponemos el que sea el día martes 13 de enero. Quedamos atentos. Muchas gracias. | K3: high | L3: pending | M3: 20254050952987 | N3: 20254050952987 | P3: 20265216319003 | Q3: 14481465021595 | R3: FALSE | S3: TRUE | T3: 14952899745563 | U3: Z4W9K5-JDDWP | V3: 20427286020763 | W3: 14481427110299 | X3: FALSE | Y3: TRUE | Z3: FALSE | AA3: agent | AB3: web | AC3: unoffered | AD3: axesse, barcoding, braquiterapia, dosisoft, elekta, físico, hardware_y_software, infinity, iview, linac, monaco, monacosim, mosaiq, no, problema, storage, versahd, xvi | AF3: dosisoft | AG3: no | AH3: problema | AK3: 01K2MWGQVK5P8BZ4P54MS8055Q
A4: https://eygmedicalsystems.zendesk.com/api/v2/tickets/9801.json | B4: 9801 | C4: {=IF( ISNUMBER(MATCH(B4, Reporte_Tickets_Detallado!C:C, 0)), "Vinculado (" & INDEX(Reporte_Tickets_Detallado!B:B, MATCH(B4, Reporte_Tickets_Detallado!C:C, 0)) & ")", "Sin Tarea" )} -> Vinculado (3459) | D4: 46030.804 | E4: 46032.543 | F4: 1768050106 | G4: incident | H4: Gantry Stop-Infinity detenido - se requiere atencion en terreno lo antes posible | I4: Gantry Stop-Infinity detenido - se requiere atencion en terreno lo antes posible | J4: Gantry Stop, Infinity detenido - se requiere atencion en terreno lo antes posible. Los esperamos. Gracias ! | K4: urgent | L4: solved | M4: 20254050947483 | N4: 20254050947483 | O4: 22297930568347 | P4: 14741593614363 | Q4: 14481465021595 | R4: FALSE | S4: TRUE | T4: 14481439499675 | U4: PWR9K5-G59ML | V4: 20427286020763 | W4: 14481427110299 | X4: FALSE | Y4: TRUE | Z4: FALSE | AA4: agent | AB4: web | AC4: offered | AD4: citrix, elekta, físico, hardware_y_software, infinity, integrity, iview, linac, media, monaco, mosaiq, problema, si, storage, suncheck_machine, sunnuclear, xvi | AF4: integrity | AG4: si | AH4: problema | AK4: 01K2MWR2KCZK72HY0ZV2CSMFTN
A5: https://eygmedicalsystems.zendesk.com/api/v2/tickets/9800.json | B5: 9800 | C5: {=IF( ISNUMBER(MATCH(B5, Reporte_Tickets_Detallado!C:C, 0)), "Vinculado (" & INDEX(Reporte_Tickets_Detallado!B:B, MATCH(B5, Reporte_Tickets_Detallado!C:C, 0)) & ")", "Sin Tarea" )} -> Sin Tarea | D5: 46030.601 | E5: 46030.601 | F5: 1767882303 | G5: incident | H5: Solicitud de actualizacion de licencias productos Sunnuclear | I5: Solicitud de actualizacion de licencias productos Sunnuclear | J5: Estimados, Junto con saludar, solicitamos que se realice de manera urgente la actualizacion de las licencias de los productos de Sunnuclear adquiridos en sede norte correspondientes al contrato asociado al equipo Elekta Infinity. Adjuntamos imagenes de los productos asociados. Quedamos atentos, Saludos cordiales. | K5: urgent | L5: new | M5: 20254050948123 | N5: 20254050948123 | P5: 14741593614363 | Q5: 14481465021595 | R5: FALSE | S5: TRUE | T5: 14481427193115 | U5: Z4RPWR-MNWPP | V5: 20427286020763 | W5: 14481427110299 | X5: FALSE | Y5: TRUE | Z5: FALSE | AA5: agent | AB5: web | AC5: unoffered | AD5: citrix, elekta, físico, hardware_y_software, infinity, integrity, iview, linac, media, monaco, mosaiq, no, problema, storage, suncheck_machine, sunnuclear, xvi | AF5: integrity | AG5: no | AH5: problema | AK5: 01K2MWR2KCZK72HY0ZV2CSMFTN
